Workbook

Sheet all_correspondences
A1: windc_sector | B1: windc_desc | C1: bea_summary | D1: bea_summary_desc | E1: oecd_code | F1: OECD ICIO Industry | G1: flag (0=possibilities, 1=error,2=ambiguous,3=perfect match) | H1: proposed sector | I1: which is larger?
A2: ote | B2: Other transportation equipment (3364OT) | C2: 3364OT | D2: Other transportation equipment | E2: C301 | F2: Building of ships and boats | G2: 0 | H2: Manufacture of other transport equipment | I2: windc
A3: adm | B3: Administrative and support services (561) | C3: 561 | D3: Administrative and support services | E3: N | F3: Administrative and support service activities | G3: 3 | H3: Administrative and support service activities | I3: match
A4: air | B4: Air transportation (481) | C4: 481 | D4: Air transportation | E4: H51 | F4: Air transport | G4: 3 | H4: Air transport | I4: match
A5: con | B5: Construction (23) | C5: 23 | D5: Construction | E5: F | F5: Construction | G5: 3 | H5: Construction | I5: match
A6: edu | B6: Educational services (61) | C6: 61 | D6: Educational services | E6: P | F6: Education | G6: 3 | H6: Education | I6: match
A7: uti | B7: Utilities (22) | C7: 22 | D7: Utilities | E7: D | F7: Electricity, gas, steam and air conditioning supply | G7: 3 | H7: Electricity, gas, steam and air conditioning supply | I7: match
A8: pip | B8: Pipeline transportation (486) | C8: 486 | D8: Pipeline transportation | E8: H49 | F8: Land transport and transport via pipelines | G8: 3 | H8: Land transport and transport via pipelines | I8: match
A9: pet | B9: Petroleum and coal products (324) | C9: 324 | D9: Petroleum and coal products | E9: C19 | F9: Manufacture of coke and refined petroleum products | G9: 0 | H9: Manufacture of coke and refined petroleum products | I9: match
A10: cep | B10: Computer and electronic products (334) | C10: 334 | D10: Computer and electronic products | E10: C26 | F10: Manufacture of computer, electronic and optical products | G10: 0 | H10: Manufacture of computer, electronic and optical products | I10: match
A11: eec | B11: Electrical equipment, appliances, and components (335) | C11: 335 | D11: Electrical equipment, appliances, and components | E11: C27 | F11: Manufacture of electrical equipment | G11: 3 | H11: Manufacture of electrical equipment | I11: match
A12: fmt | B12: Fabricated metal products (332) | C12: 332 | D12: Fabricated metal products | E12: C25 | F12: Manufacture of fabricated metal products | G12: 3 | H12: Manufacture of fabricated metal products | I12: match
A13: fbp | B13: Food and beverage and tobacco products (311FT) | C13: 311FT | D13: Food and beverage and tobacco products | E13: C10T12 | F13: Manufacture of food products | G13: 3 | H13: Manufacture of food and beverage and tobacco products | I13: match
A14: fpd | B14: Furniture and related products (337) | C14: 337 | D14: Furniture and related products | E14: C31T33 | F14: Manufacture of furniture | G14: 3 | H14: Manufacture of furniture | I14: match
A15: mch | B15: Machinery (333) | C15: 333 | D15: Machinery | E15: C28 | F15: Manufacture of machinery and equipment n.e.c. | G15: 3 | H15: Manufacture of machinery and equipment n.e.c. | I15: match
A16: mot | B16: Motor vehicles, bodies and trailers, and parts (3361MV) | C16: 3361MV | D16: Motor vehicles, bodies and trailers, and parts | E16: C29 | F16: Manufacture of motor vehicles, trailers and semi-trailers | G16: 3 | H16: Manufacture of motor vehicles, trailers and semi-trailers | I16: match
A17: nmp | B17: Nonmetallic mineral products (327) | C17: 327 | D17: Nonmetallic mineral products | E17: C23 | F17: Manufacture of other non-metallic mineral products | G17: 3 | H17: Manufacture of other non-metallic mineral products | I17: match
A18: ote | B18: Other transportation equipment (3364OT) | C18: 3364OT | D18: Other transportation equipment | E18: C302T309 | F18: Manufacture of other transport equipment | G18: 3 | H18: Manufacture of other transport equipment | I18: match
A19: pla | B19: Plastics and rubber products (326) | C19: 326 | D19: Plastics and rubber products | E19: C22 | F19: Manufacture of rubber and plastic products | G19: 3 | H19: Manufacture of rubber and plastic products | I19: match
A20: wpd | B20: Wood products (321) | C20: 321 | D20: Wood products | E20: C16 | F20: Manufacture of wood and of products of wood and cork | G20: 0 | H20: Manufacture of wood and of products of wood and cork | I20: match
A21: oil | B21: Oil and gas extraction (211) | C21: 211 | D21: Oil and gas extraction | E21: B06 | F21: Extraction of crude petroleum and natural gas | G21: 3 | H21: Oil and gas extraction | I21: match
A22: osv | B22: Other services, except government (81) | C22: 81 | D22: Other services, except government | E22: S | F22: Other service activities | G22: 0 | H22: Other service activities | I22: match
A23: tsv | B23: Miscellaneous professional, scientific, and technical services (5412OP) | C23: 5412OP | D23: Miscellaneous professional, scientific, and technical services | E23: M | F23: Professional, scientific and technical activities | G23: 3 | H23: Professional, scientific and technical activities | I23: match
A24: smn | B24: Support activities for mining (213) | C24: 213 | D24: Support activities for mining | E24: B09 | F24: Mining support service activities | G24: 3 | H24: Support activities for mining | I24: match
A25: wtt | B25: Water transportation (483) | C25: 483 | D25: Water transportation | E25: H50 | F25: Water transport | G25: 3 | H25: Water transport | I25: match
A26: agr | B26: Farms (111CA) | C26: 111CA | D26: Farms | E26: A01 | F26: Agriculture and hunting | G26: 0 | H26: Agriculture, hunting, forestry, fishing and related | I26: none
A27: fof | B27: Forestry, fishing, and related activities (113FF) | C27: 113FF | D27: Forestry, fishing, and related activities | E27: A01 | F27: Agriculture and hunting | G27: 0 | H27: Agriculture, hunting, forestry, fishing and related | I27: none
A28: agr | B28: Farms (111CA) | C28: 111CA | D28: Farms | E28: A02 | F28: Forestry and logging | G28: 0 | H28: Agriculture, hunting, forestry, fishing and related | I28: none
A29: fof | B29: Forestry, fishing, and related activities (113FF) | C29: 113FF | D29: Forestry, fishing, and related activities | E29: A02 | F29: Forestry and logging | G29: 0 | H29: Agriculture, hunting, forestry, fishing and related | I29: none
A30: agr | B30: Farms (111CA) | C30: 111CA | D30: Farms | E30: A03 | F30: Fishing and aquaculture | G30: 0 | H30: Agriculture, hunting, forestry, fishing and related | I30: none
A31: fof | B31: Forestry, fishing, and related activities (113FF) | C31: 113FF | D31: Forestry, fishing, and related activities | E31: A03 | F31: Fishing and aquaculture | G31: 0 | H31: Agriculture, hunting, forestry, fishing and related | I31: none
A32: brd | B32: Broadcasting and telecommunications (513) | C32: 513 | D32: Broadcasting and telecommunications | E32: J58T60 | F32: Publishing, Motion picture, video, television programme production and broadcasting activities | G32: 0 | H32: broadcasting, telecommunications, data processing, publishing, information services, motion picture, video, television | I32: none
A33: dat | B33: Data processing, internet publishing, and other information services (514) | C33: 514 | D33: Data processing, internet publishing, and other information services | E33: J58T60 | F33: Publishing, Motion picture, video, television programme production and broadcasting activities | G33: 0 | H33: broadcasting, telecommunications, data processing, publishing, information services, motion picture, video, television | I33: none
A34: mov | B34: Motion picture and sound recording industries (512) | C34: 512 | D34: Motion picture and sound recording industries | E34: J58T60 | F34: Publishing, Motion picture, video, television programme production and broadcasting activities | G34: 0 | H34: broadcasting, telecommunications, data processing, publishing, information services, motion picture, video, television | I34: none
A35: pub | B35: Publishing industries, except internet (includes software) (511) | C35: 511 | D35: Publishing industries, except internet (includes software) | E35: J58T60 | F35: Publishing, Motion picture, video, television programme production and broadcasting activities | G35: 0 | H35: broadcasting, telecommunications, data processing, publishing, information services, motion picture, video, television | I35: none
A36: brd | B36: Broadcasting and telecommunications (513) | C36: 513 | D36: Broadcasting and telecommunications | E36: J61 | F36: Telecommunications | G36: 0 | H36: broadcasting, telecommunications, data processing, publishing, information services, motion picture, video, television | I36: none
A37: osv | B37: Other services, except government (81) | C37: 81 | D37: Other services, except government | E37: J61 | F37: Telecommunications | G37: 0 | H37: X | I37: none
A38: com | B38: Computer systems design and related services (5415) | C38: 5415 | D38: Computer systems design and related services | E38: J62_63 | F38: Computer programming and information service activities | G38: 0 | H38: broadcasting, telecommunications, data processing, publishing, information services, motion picture, video, television | I38: none
A39: dat | B39: Data processing, internet publishing, and other information services (514) | C39: 514 | D39: Data processing, internet publishing, and other information services | E39: J62_63 | F39: Computer programming and information service activities | G39: 0 | H39: broadcasting, telecommunications, data processing, publishing, information services, motion picture, video, television | I39: none
A40: fbt | B40: Food and beverage stores (445) | C40: 445 | D40: Food and beverage stores | E40: G | F40: Wholesale and retail trade | G40: 0 | H40: Wholesale and retail trade, stores | I40: oecd
...

Sheet cleaned_correspondence
A1: windc_sector | B1: windc_desc | C1: bea_summary | D1: bea_summary_desc | E1: oecd_code | F1: OECD ICIO Industry | G1: flag (0=possibilities, 1=error,2=ambiguous,3=perfect match) | H1: proposed sector | I1: which is larger?
A2: ote | B2: Other transportation equipment (3364OT) | C2: 3364OT | D2: Other transportation equipment | E2: C301 | F2: Building of ships and boats | G2: 0 | H2: Manufacture of other transport equipment | I2: windc
A3: adm | B3: Administrative and support services (561) | C3: 561 | D3: Administrative and support services | E3: N | F3: Administrative and support service activities | G3: 3 | H3: Administrative and support service activities | I3: match
A4: air | B4: Air transportation (481) | C4: 481 | D4: Air transportation | E4: H51 | F4: Air transport | G4: 3 | H4: Air transport | I4: match
A5: con | B5: Construction (23) | C5: 23 | D5: Construction | E5: F | F5: Construction | G5: 3 | H5: Construction | I5: match
A6: edu | B6: Educational services (61) | C6: 61 | D6: Educational services | E6: P | F6: Education | G6: 3 | H6: Education | I6: match
A7: uti | B7: Utilities (22) | C7: 22 | D7: Utilities | E7: D | F7: Electricity, gas, steam and air conditioning supply | G7: 3 | H7: Electricity, gas, steam and air conditioning supply, and wasterwater | I7: none
A8: pip | B8: Pipeline transportation (486) | C8: 486 | D8: Pipeline transportation | E8: H49 | F8: Land transport and transport via pipelines | G8: 3 | H8: Land transport and transport via pipelines | I8: match
A9: pet | B9: Petroleum and coal products (324) | C9: 324 | D9: Petroleum and coal products | E9: C19 | F9: Manufacture of coke and refined petroleum products | G9: 0 | H9: Manufacture of coke and refined petroleum products | I9: match
A10: cep | B10: Computer and electronic products (334) | C10: 334 | D10: Computer and electronic products | E10: C26 | F10: Manufacture of computer, electronic and optical products | G10: 0 | H10: Manufacture of computer, electronic and optical products | I10: match
A11: eec | B11: Electrical equipment, appliances, and components (335) | C11: 335 | D11: Electrical equipment, appliances, and components | E11: C27 | F11: Manufacture of electrical equipment | G11: 3 | H11: Manufacture of electrical equipment | I11: match
A12: fmt | B12: Fabricated metal products (332) | C12: 332 | D12: Fabricated metal products | E12: C25 | F12: Manufacture of fabricated metal products | G12: 3 | H12: Manufacture of fabricated metal products | I12: match
A13: fbp | B13: Food and beverage and tobacco products (311FT) | C13: 311FT | D13: Food and beverage and tobacco products | E13: C10T12 | F13: Manufacture of food products | G13: 3 | H13: Manufacture of food and beverage and tobacco products | I13: match
A14: fpd | B14: Furniture and related products (337) | C14: 337 | D14: Furniture and related products | E14: C31T33 | F14: Manufacture of furniture | G14: 3 | H14: Manufacture of furniture | I14: match
A15: mch | B15: Machinery (333) | C15: 333 | D15: Machinery | E15: C28 | F15: Manufacture of machinery and equipment n.e.c. | G15: 3 | H15: Manufacture of machinery and equipment n.e.c. | I15: match
A16: mot | B16: Motor vehicles, bodies and trailers, and parts (3361MV) | C16: 3361MV | D16: Motor vehicles, bodies and trailers, and parts | E16: C29 | F16: Manufacture of motor vehicles, trailers and semi-trailers | G16: 3 | H16: Manufacture of motor vehicles, trailers and semi-trailers | I16: match
A17: nmp | B17: Nonmetallic mineral products (327) | C17: 327 | D17: Nonmetallic mineral products | E17: C23 | F17: Manufacture of other non-metallic mineral products | G17: 3 | H17: Manufacture of other non-metallic mineral products | I17: match
A18: ote | B18: Other transportation equipment (3364OT) | C18: 3364OT | D18: Other transportation equipment | E18: C302T309 | F18: Manufacture of other transport equipment | G18: 3 | H18: Manufacture of other transport equipment | I18: match
A19: pla | B19: Plastics and rubber products (326) | C19: 326 | D19: Plastics and rubber products | E19: C22 | F19: Manufacture of rubber and plastic products | G19: 3 | H19: Manufacture of rubber and plastic products | I19: match
A20: wpd | B20: Wood products (321) | C20: 321 | D20: Wood products | E20: C16 | F20: Manufacture of wood and of products of wood and cork | G20: 0 | H20: Manufacture of wood and of products of wood and cork | I20: match
A21: oil | B21: Oil and gas extraction (211) | C21: 211 | D21: Oil and gas extraction | E21: B06 | F21: Extraction of crude petroleum and natural gas | G21: 3 | H21: Oil and gas extraction | I21: match
A22: osv | B22: Other services, except government (81) | C22: 81 | D22: Other services, except government | E22: S | F22: Other service activities | G22: 0 | H22: Other service activities | I22: match
A23: tsv | B23: Miscellaneous professional, scientific, and technical services (5412OP) | C23: 5412OP | D23: Miscellaneous professional, scientific, and technical services | E23: M | F23: Professional, scientific and technical activities | G23: 3 | H23: Professional, scientific and technical activities | I23: match
A24: smn | B24: Support activities for mining (213) | C24: 213 | D24: Support activities for mining | E24: B09 | F24: Mining support service activities | G24: 3 | H24: Support activities for mining | I24: match
A25: wtt | B25: Water transportation (483) | C25: 483 | D25: Water transportation | E25: H50 | F25: Water transport | G25: 3 | H25: Water transport | I25: match
A26: agr | B26: Farms (111CA) | C26: 111CA | D26: Farms | E26: A01 | F26: Agriculture and hunting | G26: 0 | H26: Agriculture, hunting, forestry, fishing and related | I26: none
A27: fof | B27: Forestry, fishing, and related activities (113FF) | C27: 113FF | D27: Forestry, fishing, and related activities | E27: A01 | F27: Agriculture and hunting | G27: 0 | H27: Agriculture, hunting, forestry, fishing and related | I27: none
A28: agr | B28: Farms (111CA) | C28: 111CA | D28: Farms | E28: A02 | F28: Forestry and logging | G28: 0 | H28: Agriculture, hunting, forestry, fishing and related | I28: none
A29: fof | B29: Forestry, fishing, and related activities (113FF) | C29: 113FF | D29: Forestry, fishing, and related activities | E29: A02 | F29: Forestry and logging | G29: 0 | H29: Agriculture, hunting, forestry, fishing and related | I29: none
A30: agr | B30: Farms (111CA) | C30: 111CA | D30: Farms | E30: A03 | F30: Fishing and aquaculture | G30: 0 | H30: Agriculture, hunting, forestry, fishing and related | I30: none
A31: fof | B31: Forestry, fishing, and related activities (113FF) | C31: 113FF | D31: Forestry, fishing, and related activities | E31: A03 | F31: Fishing and aquaculture | G31: 0 | H31: Agriculture, hunting, forestry, fishing and related | I31: none
A32: brd | B32: Broadcasting and telecommunications (513) | C32: 513 | D32: Broadcasting and telecommunications | E32: J58T60 | F32: Publishing, Motion picture, video, television programme production and broadcasting activities | G32: 0 | H32: broadcasting, telecommunications, data processing, publishing, information services, motion picture, video, television | I32: none
A33: dat | B33: Data processing, internet publishing, and other information services (514) | C33: 514 | D33: Data processing, internet publishing, and other information services | E33: J58T60 | F33: Publishing, Motion picture, video, television programme production and broadcasting activities | G33: 0 | H33: broadcasting, telecommunications, data processing, publishing, information services, motion picture, video, television | I33: none
A34: mov | B34: Motion picture and sound recording industries (512) | C34: 512 | D34: Motion picture and sound recording industries | E34: J58T60 | F34: Publishing, Motion picture, video, television programme production and broadcasting activities | G34: 0 | H34: broadcasting, telecommunications, data processing, publishing, information services, motion picture, video, television | I34: none
A35: pub | B35: Publishing industries, except internet (includes software) (511) | C35: 511 | D35: Publishing industries, except internet (includes software) | E35: J58T60 | F35: Publishing, Motion picture, video, television programme production and broadcasting activities | G35: 0 | H35: broadcasting, telecommunications, data processing, publishing, information services, motion picture, video, television | I35: none
A36: brd | B36: Broadcasting and telecommunications (513) | C36: 513 | D36: Broadcasting and telecommunications | E36: J61 | F36: Telecommunications | G36: 0 | H36: broadcasting, telecommunications, data processing, publishing, information services, motion picture, video, television | I36: none
A37: com | B37: Computer systems design and related services (5415) | C37: 5415 | D37: Computer systems design and related services | E37: J62_63 | F37: Computer programming and information service activities | G37: 0 | H37: broadcasting, telecommunications, data processing, publishing, information services, motion picture, video, television | I37: none
A38: dat | B38: Data processing, internet publishing, and other information services (514) | C38: 514 | D38: Data processing, internet publishing, and other information services | E38: J62_63 | F38: Computer programming and information service activities | G38: 0 | H38: broadcasting, telecommunications, data processing, publishing, information services, motion picture, video, television | I38: none
A39: fbt | B39: Food and beverage stores (445) | C39: 445 | D39: Food and beverage stores | E39: G | F39: Wholesale and retail trade | G39: 0 | H39: Wholesale and retail trade, stores | I39: oecd
A40: gmt | B40: General merchandise stores (452) | C40: 452 | D40: General merchandise stores | E40: G | F40: Wholesale and retail trade | G40: 0 | H40: Wholesale and retail trade, stores | I40: oecd
...

Sheet new_sectors
A1: Accommodation and food service activities | B1: oecd
A2: Administrative and support service activities | B2: match
A3: Agriculture, hunting, forestry, fishing and related | B3: none
A4: Air transport | B4: match
A5: Arts, entertainment and recreation activities | B5: oecd
A6: broadcasting, telecommunications, data processing, publishing, information services, motion picture, video, television | B6: none
A7: Construction | B7: match
A8: Education | B8: match
A9: Electricity, gas, steam and air conditioning supply, and wasterwater | B9: none
A10: Federal government enterprises (GFE) | B10: windc
A11: Financial and insurance activities | B11: oecd
A12: Human health and social work activities | B12: oecd
... A40: Wholesale and retail trade, stores | B40: none

Sheet unique_windc_sectors
A1: adm | B1: =IF(COUNTIF(cleaned_correspondence!A:A,A1)=0,"MANQUANT","OK") -> OK
A2: agr | B2: =IF(COUNTIF(cleaned_correspondence!A:A,A2)=0,"MANQUANT","OK") -> OK
A3: air | B3: =IF(COUNTIF(cleaned_correspondence!A:A,A3)=0,"MANQUANT","OK") -> OK
A4: alt | B4: =IF(COUNTIF(cleaned_correspondence!A:A,A4)=0,"MANQUANT","OK") -> OK
A5: amb | B5: =IF(COUNTIF(cleaned_correspondence!A:A,A5)=0,"MANQUANT","OK") -> OK
A6: amd | B6: =IF(COUNTIF(cleaned_correspondence!A:A,A6)=0,"MANQUANT","OK") -> OK
A7: art | B7: =IF(COUNTIF(cleaned_correspondence!A:A,A7)=0,"MANQUANT","OK") -> OK
A8: bnk | B8: =IF(COUNTIF(cleaned_correspondence!A:A,A8)=0,"MANQUANT","OK") -> OK
A9: brd | B9: =IF(COUNTIF(cleaned_correspondence!A:A,A9)=0,"MANQUANT","OK") -> OK
A10: cep | B10: =IF(COUNTIF(cleaned_correspondence!A:A,A10)=0,"MANQUANT","OK") -> OK
A11: che | B11: =IF(COUNTIF(cleaned_correspondence!A:A,A11)=0,"MANQUANT","OK") -> OK
A12: com | B12: =IF(COUNTIF(cleaned_correspondence!A:A,A12)=0,"MANQUANT","OK") -> OK
... A71: wtt | B71: =IF(COUNTIF(cleaned_correspondence!A:A,A71)=0,"MANQUANT","OK") -> OK

Sheet unique_oecd_sectors
A1: A01 | B1: =IF(COUNTIF(cleaned_correspondence!E:E,A1)=0,"MANQUANT","OK") -> OK
A2: A02 | B2: =IF(COUNTIF(cleaned_correspondence!E:E,A2)=0,"MANQUANT","OK") -> OK
A3: A03 | B3: =IF(COUNTIF(cleaned_correspondence!E:E,A3)=0,"MANQUANT","OK") -> OK
A4: B05 | B4: =IF(COUNTIF(cleaned_correspondence!E:E,A4)=0,"MANQUANT","OK") -> OK
A5: B06 | B5: =IF(COUNTIF(cleaned_correspondence!E:E,A5)=0,"MANQUANT","OK") -> OK
A6: B07 | B6: =IF(COUNTIF(cleaned_correspondence!E:E,A6)=0,"MANQUANT","OK") -> OK
A7: B08 | B7: =IF(COUNTIF(cleaned_correspondence!E:E,A7)=0,"MANQUANT","OK") -> OK
A8: B09 | B8: =IF(COUNTIF(cleaned_correspondence!E:E,A8)=0,"MANQUANT","OK") -> OK
A9: C10T12 | B9: =IF(COUNTIF(cleaned_correspondence!E:E,A9)=0,"MANQUANT","OK") -> OK
A10: C13T15 | B10: =IF(COUNTIF(cleaned_correspondence!E:E,A10)=0,"MANQUANT","OK") -> OK
A11: C16 | B11: =IF(COUNTIF(cleaned_correspondence!E:E,A11)=0,"MANQUANT","OK") -> OK
A12: C17_18 | B12: =IF(COUNTIF(cleaned_correspondence!E:E,A12)=0,"MANQUANT","OK") -> OK
... A50: T | B50: =IF(COUNTIF(cleaned_correspondence!E:E,A50)=0,"MANQUANT","OK") -> MANQUANT
